Workbook

Sheet README
A1: UK Payday Probability Model Specification
A2: Purpose | B2: Blueprint workbook structure and specification
A4: Worksheet | B4: Description
A5: Sources | B5: Specification/data sheet for Sources
A6: Population_Data | B6: Specification/data sheet for Population_Data
A7: Monthly_Pay_Model | B7: Specification/data sheet for Monthly_Pay_Model
A8: Weekly_Model | B8: Specification/data sheet for Weekly_Model
A9: Fortnightly_Model | B9: Specification/data sheet for Fortnightly_Model
A10: FourWeekly_Model | B10: Specification/data sheet for FourWeekly_Model
A11: Bank_Holidays | B11: Specification/data sheet for Bank_Holidays
A12: Calendar | B12: Specification/data sheet for Calendar
A13: Daily_Calculations | B13: Specification/data sheet for Daily_Calculations
A14: Sensitivity | B14: Specification/data sheet for Sensitivity
... A19: Data_Lineage | B19: Specification/data sheet for Data_Lineage

Sheet Sources
A1: Source ID | B1: Organisation | C1: Dataset | D1: Publication Date | E1: URL | F1: Statistic Used | G1: Confidence | H1: Notes
A2: SRC001 | B2: ONS | C2: ASHE Pay Frequency | F2: Employee pay frequency
A3: SRC002 | B3: HMRC | C3: PAYE RTI | F3: Payroll methodology
A4: SRC003 | B4: GOV.UK | C4: Bank Holidays | F4: Holiday calendar

Sheet Supbase
A1: Date | B1: Disposable Income
A2: =Daily_Calculations!$A2 -> 46235 | B2: =Daily_Calculations!$U2 -> 0
A3: =Daily_Calculations!$A3 -> 46236 | B3: =Daily_Calculations!$U3 -> 0
A4: =Daily_Calculations!$A4 -> 46237 | B4: =Daily_Calculations!$U4 -> 0.027559498
A5: =Daily_Calculations!$A5 -> 46238 | B5: =Daily_Calculations!$U5 -> 0.027559498
A6: =Daily_Calculations!$A6 -> 46239 | B6: =Daily_Calculations!$U6 -> 0.031127721
A7: =Daily_Calculations!$A7 -> 46240 | B7: =Daily_Calculations!$U7 -> 0.028897582
A8: =Daily_Calculations!$A8 -> 46241 | B8: =Daily_Calculations!$U8 -> 0.03461223
A9: =Daily_Calculations!$A9 -> 46242 | B9: =Daily_Calculations!$U9 -> 0
A10: =Daily_Calculations!$A10 -> 46243 | B10: =Daily_Calculations!$U10 -> 0
A11: =Daily_Calculations!$A11 -> 46244 | B11: =Daily_Calculations!$U11 -> 0.029789637
A12: =Daily_Calculations!$A12 -> 46245 | B12: =Daily_Calculations!$U12 -> 0.027559498
A13: =Daily_Calculations!$A13 -> 46246 | B13: =Daily_Calculations!$U13 -> 0.028005526
... A532: =Daily_Calculations!$A532 -> 46765 | B532: =Daily_Calculations!$U532 -> 0.027559498

Sheet Population_Data
A1: Metric | B1: Value | C1: Unit | D1: Source ID | E1: Editable | F1: Notes
A2: UK Employee Jobs | B2: 36800000 | C2: Jobs | D2: SRC001 | E2: No | F2: https://www.ons.gov.uk/employmentandlabourmarket/peopleinwork/employmentandemployeetypes/bulletins/uklabourmarket/june2026/pdf
A3: Monthly Pay Frequency | B3: 0.776 | C3: % | D3: SRC001 | E3: No | F3: https://www.ons.gov.uk/file?uri=/employmentandlabourmarket/peopleinwork/earningsandworkinghours/adhocs/14237annualsurveyofhoursandearningsasheproportionofallemployeejobswithweeklyfortnightlyfourweeklyandmonthlypayperiodsukapril2021/k83payperiodproportion2021.xls
A4: Weekly Pay Frequency | B4: 0.116 | C4: % | D4: SRC001 | E4: No | F4: https://www.ons.gov.uk/file?uri=/employmentandlabourmarket/peopleinwork/earningsandworkinghours/adhocs/14237annualsurveyofhoursandearningsasheproportionofallemployeejobswithweeklyfortnightlyfourweeklyandmonthlypayperiodsukapril2021/k83payperiodproportion2021.xls
A5: Fortnightly Pay Frequency | B5: 0.015 | C5: % | D5: SRC001 | E5: No | F5: https://www.ons.gov.uk/file?uri=/employmentandlabourmarket/peopleinwork/earningsandworkinghours/adhocs/14237annualsurveyofhoursandearningsasheproportionofallemployeejobswithweeklyfortnightlyfourweeklyandmonthlypayperiodsukapril2021/k83payperiodproportion2021.xls
A6: Four-weekly Pay Frequency | B6: 0.093 | C6: % | D6: SRC001 | E6: No | F6: https://www.ons.gov.uk/file?uri=/employmentandlabourmarket/peopleinwork/earningsandworkinghours/adhocs/14237annualsurveyofhoursandearningsasheproportionofallemployeejobswithweeklyfortnightlyfourweeklyandmonthlypayperiodsukapril2021/k83payperiodproportion2021.xls
A7: Other Pay Frequencies | B7: 0 | C7: % | D7: SRC001 | E7: No | F7: https://www.ons.gov.uk/file?uri=/employmentandlabourmarket/peopleinwork/earningsandworkinghours/adhocs/14237annualsurveyofhoursandearningsasheproportionofallemployeejobswithweeklyfortnightlyfourweeklyandmonthlypayperiodsukapril2021/k83payperiodproportion2021.xls
A8: UK Employees (PAYE RTI latest) | B8: 30300000 | C8: People | D8: SRC002 | E8: No | F8: https://www.ons.gov.uk/employmentandlabourmarket/peopleinwork/employmentandemployeetypes/bulletins/uklabourmarket/july2026/pdf
A9: Monthly Model Base | B9: =B3 -> 0.776 | C9: % | D9: Formula | E9: Yes | F9: Links to source
A10: Weekly Model Base | B10: =B4 -> 0.116 | C10: % | D10: Formula | E10: Yes | F10: Links to source
A11: Fortnightly Model Base | B11: =B5 -> 0.015 | C11: % | D11: Formula | E11: Yes | F11: Links to source
A12: Four-weekly Model Base | B12: =B6 -> 0.093 | C12: % | D12: Formula | E12: Yes | F12: Links to source
A13: Total Check | B13: =SUM(B9:B12) -> 1 | C13: % | D13: Formula | E13: No | F13: Should equal 100%
A15: Pensioners | B15: 13212000
B16: 1
A19: 18+ | B19: 55200000

Sheet Monthly_Pay_Model
A1: Pattern ID | B1: Payday Pattern | C1: Base Day | D1: Share of UK total Employees | E1: Share of Monthly Employees | F1: Editable | G1: Evidence | H1: Notes | N1: Total Share | Q1: =SUM(E2:E6) -> 1
A2: MP01 | B2: Last Working Day | C2: Variable | D2: =E2*Population_Data!$B$3 -> 0.28712 | E2: 0.37 | F2: Yes | G2: Payroll Statistics Survey 2024 | H2: Most common monthly payday (FlippingBook) | Q2: =IF(ABS(Q1-100%)<0.0001,"PASS","CHECK") -> PASS
A3: MP02 | B3: Last Day of Month | C3: Variable | D3: =E3*Population_Data!$B$3 -> 0.12416 | E3: 0.16 | F3: Yes | G3: Payroll Statistics Survey 2024 | H3: Calendar month end (FlippingBook)
A4: MP03 | B4: Last Friday | C4: Variable | D4: =E4*Population_Data!$B$3 -> 0.1552 | E4: 0.2 | F4: Yes | G4: Payroll Statistics Survey 2024 | H4: Common private-sector payroll (FlippingBook)
A5: MP07 | B5: Last Thursday | C5: Variable | D5: =E5*Population_Data!$B$3 -> 0.05432 | E5: 0.07 | F5: Yes | G5: Payroll Statistics Survey 2024 | H5: Published survey result (FlippingBook)
B6: Set Date of Week | D6: =E6*Population_Data!$B$3 -> 0.1552 | E6: 0.2
G7: =SUM(1/D6) -> 6.443299
A8: Survey Total | B8: Distibuted to account for 20% of answers | C8: Day of Month | D8: Total Share of UK employees (split by
A9: 0.05 | B9: =(A9/$A$40)/$G$7 -> 0.0040628272 | C9: 01 | D9: =(A9/$A$40)/$G$7 -> 0.0040628272 | F9: Yes
A10: 0.01 | B10: =(A10/$A$40)/$G$7 -> 0.00081256545 | C10: 02 | D10: =(A10/$A$40)/$G$7 -> 0.00081256545 | F10: Yes
A11: 0.01 | B11: =(A11/$A$40)/$G$7 -> 0.00081256545 | C11: 03 | D11: =(A11/$A$40)/$G$7 -> 0.00081256545 | F11: Yes
A12: 0.01 | B12: =(A12/$A$40)/$G$7 -> 0.00081256545 | C12: 04 | D12: =(A12/$A$40)/$G$7 -> 0.00081256545 | F12: Yes
A13: 0.09 | B13: =(A13/$A$40)/$G$7 -> 0.007313089 | C13: 05 | D13: =(A13/$A$40)/$G$7 -> 0.007313089 | F13: Yes
A14: 0.04 | B14: =(A14/$A$40)/$G$7 -> 0.0032502618 | C14: 06 | D14: =(A14/$A$40)/$G$7 -> 0.0032502618 | F14: Yes
A15: 0.03 | B15: =(A15/$A$40)/$G$7 -> 0.0024376963 | C15: 07 | D15: =(A15/$A$40)/$G$7 -> 0.0024376963 | F15: Yes
A16: 0.02 | B16: =(A16/$A$40)/$G$7 -> 0.0016251309 | C16: 08 | D16: =(A16/$A$40)/$G$7 -> 0.0016251309 | F16: Yes
A17: 0.01 | B17: =(A17/$A$40)/$G$7 -> 0.00081256545 | C17: 09 | D17: =(A17/$A$40)/$G$7 -> 0.00081256545 | F17: Yes
A18: 0.06 | B18: =(A18/$A$40)/$G$7 -> 0.0048753927 | C18: 10 | D18: =(A18/$A$40)/$G$7 -> 0.0048753927 | F18: Yes
A19: 0.01 | B19: =(A19/$A$40)/$G$7 -> 0.00081256545 | C19: 11 | D19: =(A19/$A$40)/$G$7 -> 0.00081256545 | F19: Yes
A20: 0.02 | B20: =(A20/$A$40)/$G$7 -> 0.0016251309 | C20: 12 | D20: =(A20/$A$40)/$G$7 -> 0.0016251309 | F20: Yes
... A39: 0.07 | B39: =(A39/$A$40)/$G$7 -> 0.0056879581 | C39: 31 | D39: =(A39/$A$40)/$G$7 -> 0.0056879581 | F39: Yes
A40: =SUM(A9:A39) -> 1.91 | B40: =(A40/$A$40)/$G$7 -> 0.1552
D41: =SUM(D9:D39) -> 0.1552

Sheet Weekly_Model
A1: Weekday | B1: Share of Weekly Paid Employees | C1: Weekly Frequency Formula | D1: Overall Population Formula | E1: Editable | F1: Evidence | G1: Notes
A2: Monday | B2: 0.2 | C2: =B2 -> 0.2 | D2: =Population_Data!B4*B2 -> 0.0232 | E2: Yes | F2: Assumption | G2: Equal weekday distribution
A3: Tuesday | B3: 0.2 | C3: =B3 -> 0.2 | D3: =Population_Data!B4*B3 -> 0.0232 | E3: Yes | F3: Assumption | G3: Equal weekday distribution
A4: Wednesday | B4: 0.2 | C4: =B4 -> 0.2 | D4: =Population_Data!B4*B4 -> 0.0232 | E4: Yes | F4: Assumption | G4: Equal weekday distribution
A5: Thursday | B5: 0.2 | C5: =B5 -> 0.2 | D5: =Population_Data!B4*B5 -> 0.0232 | E5: Yes | F5: Assumption | G5: Equal weekday distribution
A6: Friday | B6: 0.2 | C6: =B6 -> 0.2 | D6: =Population_Data!B4*B6 -> 0.0232 | E6: Yes | F6: Assumption | G6: Equal weekday distribution
A7: Saturday | B7: 0 | C7: =B7 -> 0 | D7: =Population_Data!B4*B7 -> 0 | E7: Yes | F7: Assumption | G7: Rare payroll processing
A8: Sunday | B8: 0 | C8: =B8 -> 0 | D8: =Population_Data!B4*B8 -> 0 | E8: Yes | F8: Assumption | G8: Rare payroll processing
A9: Total | B9: =SUM(B2:B8) -> 1 | D9: =SUM(D2:D8) -> 0.116 | G9: Should equal 100% of weekly-paid employees

Sheet Fortnightly_Model
A1: Cohort | B1: Anchor Offset (Days) | C1: Share of Fortnightly Employees | D1: Overall Population Formula | E1: Editable | F1: Notes
A2: F01 | B2: 0 | C2: 0 | D2: =Population_Data!B5*C2 -> 0 | E2: Yes | F2: Day 0 of cycle
A3: F02 | B3: 1 | C3: 0 | D3: =Population_Data!B5*C3 -> 0 | E3: Yes | F3: Day 1
A4: F03 | B4: 2 | C4: 0.07142857 | D4: =Population_Data!B5*C4 -> 0.0010714285 | E4: Yes | F4: Day 2
A5: F04 | B5: 3 | C5: 0.07142857 | D5: =Population_Data!B5*C5 -> 0.0010714285 | E5: Yes | F5: Day 3
A6: F05 | B6: 4 | C6: 0.07142857 | D6: =Population_Data!B5*C6 -> 0.0010714285 | E6: Yes | F6: Day 4
A7: F06 | B7: 5 | C7: 0.07142857 | D7: =Population_Data!B5*C7 -> 0.0010714285 | E7: Yes | F7: Day 5
A8: F07 | B8: 6 | C8: 0.21428571 | D8: =Population_Data!B5*C8 -> 0.0032142856 | E8: Yes | F8: Day 6
A9: F08 | B9: 7 | C9: 0 | D9: =Population_Data!B5*C9 -> 0 | E9: Yes | F9: Day 7
A10: F09 | B10: 8 | C10: 0 | D10: =Population_Data!B5*C10 -> 0 | E10: Yes | F10: Day 8
A11: F10 | B11: 9 | C11: 0.07142857 | D11: =Population_Data!B5*C11 -> 0.0010714285 | E11: Yes | F11: Day 9
A12: F11 | B12: 10 | C12: 0.07142857 | D12: =Population_Data!B5*C12 -> 0.0010714285 | E12: Yes | F12: Day 10
A13: F12 | B13: 11 | C13: 0.07142857 | D13: =Population_Data!B5*C13 -> 0.0010714285 | E13: Yes | F13: Day 11
A14: F13 | B14: 12 | C14: 0.07142857 | D14: =Population_Data!B5*C14 -> 0.0010714285 | E14: Yes | F14: Day 12
A15: F14 | B15: 13 | C15: 0.21428571 | D15: =Population_Data!B5*C15 -> 0.0032142856 | E15: Yes | F15: Day 13
A16: Total | C16: =SUM(C2:C15) -> 0.99999998 | D16: =SUM(D2:D15) -> 0.015 | F16: Should equal 100%

Sheet FourWeekly_Model
A1: Cohort | B1: Offset (Days) | C1: Share of Four-Weekly Employees | D1: Overall Population Formula | E1: Editable | F1: Notes
A2: FW01 | B2: 0 | C2: 0 | D2: =Population_Data!B6*C2 -> 0 | E2: Yes | F2: Day 0
A3: FW02 | B3: 1 | C3: 0 | D3: =Population_Data!B6*C3 -> 0 | E3: Yes | F3: Day 1
A4: FW03 | B4: 2 | C4: 0.03571429 | D4: =Population_Data!B6*C4 -> 0.003321429 | E4: Yes | F4: Day 2
A5: FW04 | B5: 3 | C5: 0.03571429 | D5: =Population_Data!B6*C5 -> 0.003321429 | E5: Yes | F5: Day 3
A6: FW05 | B6: 4 | C6: 0.03571429 | D6: =Population_Data!B6*C6 -> 0.003321429 | E6: Yes | F6: Day 4
A7: FW06 | B7: 5 | C7: 0.03571429 | D7: =Population_Data!B6*C7 -> 0.003321429 | E7: Yes | F7: Day 5
A8: FW07 | B8: 6 | C8: 0.10714286 | D8: =Population_Data!B6*C8 -> 0.009964286 | E8: Yes | F8: Day 6
A9: FW08 | B9: 7 | C9: 0 | D9: =Population_Data!B6*C9 -> 0 | E9: Yes | F9: Day 7
A10: FW09 | B10: 8 | C10: 0 | D10: =Population_Data!B6*C10 -> 0 | E10: Yes | F10: Day 8
A11: FW10 | B11: 9 | C11: 0.03571429 | D11: =Population_Data!B6*C11 -> 0.003321429 | E11: Yes | F11: Day 9
A12: FW11 | B12: 10 | C12: 0.03571429 | D12: =Population_Data!B6*C12 -> 0.003321429 | E12: Yes | F12: Day 10
A13: FW12 | B13: 11 | C13: 0.03571429 | D13: =Population_Data!B6*C13 -> 0.003321429 | E13: Yes | F13: Day 11
A14: FW13 | B14: 12 | C14: 0.03571429 | D14: =Population_Data!B6*C14 -> 0.003321429 | E14: Yes | F14: Day 12
A15: FW14 | B15: 13 | C15: 0.10714286 | D15: =Population_Data!B6*C15 -> 0.009964286 | E15: Yes | F15: Day 13
A16: FW15 | B16: 14 | C16: 0 | D16: =Population_Data!B6*C16 -> 0 | E16: Yes | F16: Day 14
A17: FW16 | B17: 15 | C17: 0 | D17: =Population_Data!B6*C17 -> 0 | E17: Yes | F17: Day 15
A18: FW17 | B18: 16 | C18: 0.03571429 | D18: =Population_Data!B6*C18 -> 0.003321429 | E18: Yes | F18: Day 16
A19: FW18 | B19: 17 | C19: 0.03571429 | D19: =Population_Data!B6*C19 -> 0.003321429 | E19: Yes | F19: Day 17
A20: FW19 | B20: 18 | C20: 0.03571429 | D20: =Population_Data!B6*C20 -> 0.003321429 | E20: Yes | F20: Day 18
A21: FW20 | B21: 19 | C21: 0.03571429 | D21: =Population_Data!B6*C21 -> 0.003321429 | E21: Yes | F21: Day 19
A22: FW21 | B22: 20 | C22: 0.10714286 | D22: =Population_Data!B6*C22 -> 0.009964286 | E22: Yes | F22: Day 20
A23: FW22 | B23: 21 | C23: 0 | D23: =Population_Data!B6*C23 -> 0 | E23: Yes | F23: Day 21
A24: FW23 | B24: 22 | C24: 0 | D24: =Population_Data!B6*C24 -> 0 | E24: Yes | F24: Day 22
A25: FW24 | B25: 23 | C25: 0.03571429 | D25: =Population_Data!B6*C25 -> 0.003321429 | E25: Yes | F25: Day 23
A26: FW25 | B26: 24 | C26: 0.03571429 | D26: =Population_Data!B6*C26 -> 0.003321429 | E26: Yes | F26: Day 24
A27: FW26 | B27: 25 | C27: 0.03571429 | D27: =Population_Data!B6*C27 -> 0.003321429 | E27: Yes | F27: Day 25
A28: FW27 | B28: 26 | C28: 0.03571429 | D28: =Population_Data!B6*C28 -> 0.003321429 | E28: Yes | F28: Day 26
A29: FW28 | B29: 27 | C29: 0.10714286 | D29: =Population_Data!B6*C29 -> 0.009964286 | E29: Yes | F29: Day 27
A30: Total | C30: =SUM(C2:C29) -> 1.0000001 | D30: =SUM(D2:D29) -> 0.093000007 | F30: Should equal 100%

Sheet Pension_Model
A1: Cohort | B1: Offset (Days) | C1: Share of Pensioners | D1: Overall Population Formula | E1: Editable | F1: Notes
A2: FW01 | B2: 0 | C2: 0 | D2: =Population_Data!$B$16*C2 -> 0 | E2: Yes | F2: Day 0
A3: FW02 | B3: 1 | C3: 0 | D3: =Population_Data!$B$16*C3 -> 0 | E3: Yes | F3: Day 1
A4: FW03 | B4: 2 | C4: 0.05 | D4: =Population_Data!$B$16*C4 -> 0.05 | E4: Yes | F4: Day 2
A5: FW04 | B5: 3 | C5: 0.05 | D5: =Population_Data!$B$16*C5 -> 0.05 | E5: Yes | F5: Day 3
A6: FW05 | B6: 4 | C6: 0.05 | D6: =Population_Data!$B$16*C6 -> 0.05 | E6: Yes | F6: Day 4
A7: FW06 | B7: 5 | C7: 0.05 | D7: =Population_Data!$B$16*C7 -> 0.05 | E7: Yes | F7: Day 5
A8: FW07 | B8: 6 | C8: 0.05 | D8: =Population_Data!$B$16*C8 -> 0.05 | E8: Yes | F8: Day 6
A9: FW08 | B9: 7 | C9: 0 | D9: =Population_Data!$B$16*C9 -> 0 | E9: Yes | F9: Day 7
A10: FW09 | B10: 8 | C10: 0 | D10: =Population_Data!$B$16*C10 -> 0 | E10: Yes | F10: Day 8
A11: FW10 | B11: 9 | C11: 0.05 | D11: =Population_Data!$B$16*C11 -> 0.05 | E11: Yes | F11: Day 9
A12: FW11 | B12: 10 | C12: 0.05 | D12: =Population_Data!$B$16*C12 -> 0.05 | E12: Yes | F12: Day 10
A13: FW12 | B13: 11 | C13: 0.05 | D13: =Population_Data!$B$16*C13 -> 0.05 | E13: Yes | F13: Day 11
... A29: FW28 | B29: 27 | C29: 0.05 | D29: =Population_Data!$B$16*C29 -> 0.05 | E29: Yes | F29: Day 27
A30: Total | C30: =SUM(C2:C29) -> 1 | D30: =SUM(D2:D29) -> 1 | F30: Should equal 100%

Sheet Bank_Holidays
A1: Date | B1: Holiday | C1: Nation | D1: Working Day? | E1: Adjustment Rule | F1: Notes
A2: 46023 | B2: New Year's Day | C2: England & Wales | D2: No | E2: Previous Working Day | F2: Statutory
A3: 46115 | B3: Good Friday | C3: England & Wales | D3: No | E3: Previous Working Day | F3: Statutory
A4: 46118 | B4: Easter Monday | C4: England & Wales | D4: No | E4: Previous Working Day | F4: Statutory
A5: 46146 | B5: Early May Bank Holiday | C5: England & Wales | D5: No | E5: Previous Working Day | F5: Statutory
A6: 46167 | B6: Spring Bank Holiday | C6: England & Wales | D6: No | E6: Previous Working Day | F6: Statutory
A7: 46265 | B7: Summer Bank Holiday | C7: England & Wales | D7: No | E7: Previous Working Day | F7: Statutory
A8: 46381 | B8: Christmas Day | C8: England & Wales | D8: No | E8: Previous Working Day | F8: Statutory
A9: 46384 | B9: Boxing Day (Substitute) | C9: England & Wales | D9: No | E9: Previous Working Day | F9: Statutory
A10: 46388 | B10: New Year's Day | C10: England & Wales | D10: No | E10: Previous Working Day | F10: Statutory
A11: 46472 | B11: Good Friday | C11: England & Wales | D11: No | E11: Previous Working Day | F11: Statutory
A12: 46475 | B12: Easter Monday | C12: England & Wales | D12: No | E12: Previous Working Day | F12: Statutory
A13: 46510 | B13: Early May Bank Holiday | C13: England & Wales | D13: No | E13: Previous Working Day | F13: Statutory
... A25: 47113 | B25: Boxing Day | C25: England & Wales | D25: No | E25: Previous Working Day | F25: Statutory

Sheet Calendar
A1: Date | B1: Year | C1: Month No | D1: Month | E1: Month-Year | F1: Quarter | G1: Day | H1: Weekday No | I1: Weekday | J1: Weekend? | K1: Bank Holiday? | L1: Working Day? | M1: Week Number | N1: Month End? | O1: Last Working Day? | P1: Last Friday? | Q1: Last Thursday? | R1: How many Days Pay | S1: Fortnight Offset | T1: FourWeek Offset
A2: 46235 | B2: =YEAR(A2) -> 2026 | C2: =MONTH(A2) -> 8 | D2: =TEXT(A2,"mmmm") -> August | E2: =TEXT(A2,"mmm-yy") -> Aug-26 | F2: ="Q"&ROUNDUP(MONTH($A2)/3,0) -> Q3 | G2: =DAY($A2) -> 1 | H2: =WEEKDAY($A2,2) -> 6 | I2: =TEXT($A2,"dddd") -> Saturday | J2: =IF($H2>5,"Yes","No") -> Yes | K2: =IF(COUNTIF(Bank_Holidays!A:A,A2)>0,"Yes","No") -> No | L2: =IF(AND(J2="No",K2="No"),"Yes","No") -> No | M2: =_xlfn.ISOWEEKNUM(A2) -> 31 | N2: =IF(A2=EOMONTH(A2,0),"Yes","No") -> No | O2: =IF(A2=WORKDAY(EOMONTH(A2,0)+1,-1,Bank_Holidays!$A$2:$A$25),"Yes","No") -> No | P2: =IF( AND( TEXT(A2,"dddd")="Friday", MONTH(A2+7)<>MONTH(A2) ), "Yes", "No" ) -> No | Q2: =IF( AND( TEXT(A2,"dddd")="Thursday", MONTH(A2+7)<>MONTH(A2) ), "Yes", "No" ) -> No | R2: =IF(L2="yes",1)+IF(L2="no",0,IF(AND(L7="no",L6="no",L5="no",L4="no",L3="no"),5,IF(AND(L6="no",L5="no",L4="no",L3="no"),4,IF(AND(L5="no",L4="no",L3="no"),3,IF(AND(L4="no",L3="no"),2,IF(L3="no",1)))))) -> 0 | S2: =MOD(A2-Fortnightly_Model!$M$1,14) -> 7 | T2: =MOD(A2-FourWeekly_Model!$M$1,28) -> 7
A3: =A2+1 -> 46236 | B3: =YEAR(A3) -> 2026 | C3: =MONTH(A3) -> 8 | D3: =TEXT(A3,"mmmm") -> August | E3: =TEXT(A3,"mmm-yy") -> Aug-26 | F3: ="Q"&ROUNDUP(MONTH($A3)/3,0) -> Q3 | G3: =DAY($A3) -> 2 | H3: =WEEKDAY($A3,2) -> 7 | I3: =TEXT($A3,"dddd") -> Sunday | J3: =IF($H3>5,"Yes","No") -> Yes | K3: =IF(COUNTIF(Bank_Holidays!A:A,A3)>0,"Yes","No") -> No | L3: =IF(AND(J3="No",K3="No"),"Yes","No") -> No | M3: =_xlfn.ISOWEEKNUM(A3) -> 31 | N3: =IF(A3=EOMONTH(A3,0),"Yes","No") -> No | O3: =IF(A3=WORKDAY(EOMONTH(A3,0)+1,-1,Bank_Holidays!$A$2:$A$25),"Yes","No") -> No | P3: =IF( AND( TEXT(A3,"dddd")="Friday", MONTH(A3+7)<>MONTH(A3) ), "Yes", "No" ) -> No | Q3: =IF( AND( TEXT(A3,"dddd")="Thursday", MONTH(A3+7)<>MONTH(A3) ), "Yes", "No" ) -> No | R3: =IF(L3="yes",1)+IF(L3="no",0,IF(AND(L8="no",L7="no",L6="no",L5="no",L4="no"),5,IF(AND(L7="no",L6="no",L5="no",L4="no"),4,IF(AND(L6="no",L5="no",L4="no"),3,IF(AND(L5="no",L4="no"),2,IF(L4="no",1)))))) -> 0 | S3: =MOD(A3-Fortnightly_Model!$M$1,14) -> 8 | T3: =MOD(A3-FourWeekly_Model!$M$1,28) -> 8
A4: =A3+1 -> 46237 | B4: =YEAR(A4) -> 2026 | C4: =MONTH(A4) -> 8 | D4: =TEXT(A4,"mmmm") -> August | E4: =TEXT(A4,"mmm-yy") -> Aug-26 | F4: ="Q"&ROUNDUP(MONTH($A4)/3,0) -> Q3 | G4: =DAY($A4) -> 3 | H4: =WEEKDAY($A4,2) -> 1 | I4: =TEXT($A4,"dddd") -> Monday | J4: =IF($H4>5,"Yes","No") -> No | K4: =IF(COUNTIF(Bank_Holidays!A:A,A4)>0,"Yes","No") -> No | L4: =IF(AND(J4="No",K4="No"),"Yes","No") -> Yes | M4: =_xlfn.ISOWEEKNUM(A4) -> 32 | N4: =IF(A4=EOMONTH(A4,0),"Yes","No") -> No | O4: =IF(A4=WORKDAY(EOMONTH(A4,0)+1,-1,Bank_Holidays!$A$2:$A$25),"Yes","No") -> No | P4: =IF( AND( TEXT(A4,"dddd")="Friday", MONTH(A4+7)<>MONTH(A4) ), "Yes", "No" ) -> No | Q4: =IF( AND( TEXT(A4,"dddd")="Thursday", MONTH(A4+7)<>MONTH(A4) ), "Yes", "No" ) -> No | R4: =IF(L4="yes",1)+IF(L4="no",0,IF(AND(L9="no",L8="no",L7="no",L6="no",L5="no"),5,IF(AND(L8="no",L7="no",L6="no",L5="no"),4,IF(AND(L7="no",L6="no",L5="no"),3,IF(AND(L6="no",L5="no"),2,IF(L5="no",1)))))) -> 1 | S4: =MOD(A4-Fortnightly_Model!$M$1,14) -> 9 | T4: =MOD(A4-FourWeekly_Model!$M$1,28) -> 9
A5: =A4+1 -> 46238 | B5: =YEAR(A5) -> 2026 | C5: =MONTH(A5) -> 8 | D5: =TEXT(A5,"mmmm") -> August | E5: =TEXT(A5,"mmm-yy") -> Aug-26 | F5: ="Q"&ROUNDUP(MONTH($A5)/3,0) -> Q3 | G5: =DAY($A5) -> 4 | H5: =WEEKDAY($A5,2) -> 2 | I5: =TEXT($A5,"dddd") -> Tuesday | J5: =IF($H5>5,"Yes","No") -> No | K5: =IF(COUNTIF(Bank_Holidays!A:A,A5)>0,"Yes","No") -> No | L5: =IF(AND(J5="No",K5="No"),"Yes","No") -> Yes | M5: =_xlfn.ISOWEEKNUM(A5) -> 32 | N5: =IF(A5=EOMONTH(A5,0),"Yes","No") -> No | O5: =IF(A5=WORKDAY(EOMONTH(A5,0)+1,-1,Bank_Holidays!$A$2:$A$25),"Yes","No") -> No | P5: =IF( AND( TEXT(A5,"dddd")="Friday", MONTH(A5+7)<>MONTH(A5) ), "Yes", "No" ) -> No | Q5: =IF( AND( TEXT(A5,"dddd")="Thursday", MONTH(A5+7)<>MONTH(A5) ), "Yes", "No" ) -> No | R5: =IF(L5="yes",1)+IF(L5="no",0,IF(AND(L10="no",L9="no",L8="no",L7="no",L6="no"),5,IF(AND(L9="no",L8="no",L7="no",L6="no"),4,IF(AND(L8="no",L7="no",L6="no"),3,IF(AND(L7="no",L6="no"),2,IF(L6="no",1)))))) -> 1 | S5: =MOD(A5-Fortnightly_Model!$M$1,14) -> 10 | T5: =MOD(A5-FourWeekly_Model!$M$1,28) -> 10
A6: =A5+1 -> 46239 | B6: =YEAR(A6) -> 2026 | C6: =MONTH(A6) -> 8 | D6: =TEXT(A6,"mmmm") -> August | E6: =TEXT(A6,"mmm-yy") -> Aug-26 | F6: ="Q"&ROUNDUP(MONTH($A6)/3,0) -> Q3 | G6: =DAY($A6) -> 5 | H6: =WEEKDAY($A6,2) -> 3 | I6: =TEXT($A6,"dddd") -> Wednesday | J6: =IF($H6>5,"Yes","No") -> No | K6: =IF(COUNTIF(Bank_Holidays!A:A,A6)>0,"Yes","No") -> No | L6: =IF(AND(J6="No",K6="No"),"Yes","No") -> Yes | M6: =_xlfn.ISOWEEKNUM(A6) -> 32 | N6: =IF(A6=EOMONTH(A6,0),"Yes","No") -> No | O6: =IF(A6=WORKDAY(EOMONTH(A6,0)+1,-1,Bank_Holidays!$A$2:$A$25),"Yes","No") -> No | P6: =IF( AND( TEXT(A6,"dddd")="Friday", MONTH(A6+7)<>MONTH(A6) ), "Yes", "No" ) -> No | Q6: =IF( AND( TEXT(A6,"dddd")="Thursday", MONTH(A6+7)<>MONTH(A6) ), "Yes", "No" ) -> No | R6: =IF(L6="yes",1)+IF(L6="no",0,IF(AND(L11="no",L10="no",L9="no",L8="no",L7="no"),5,IF(AND(L10="no",L9="no",L8="no",L7="no"),4,IF(AND(L9="no",L8="no",L7="no"),3,IF(AND(L8="no",L7="no"),2,IF(L7="no",1)))))) -> 1 | S6: =MOD(A6-Fortnightly_Model!$M$1,14) -> 11 | T6: =MOD(A6-FourWeekly_Model!$M$1,28) -> 11
A7: =A6+1 -> 46240 | B7: =YEAR(A7) -> 2026 | C7: =MONTH(A7) -> 8 | D7: =TEXT(A7,"mmmm") -> August | E7: =TEXT(A7,"mmm-yy") -> Aug-26 | F7: ="Q"&ROUNDUP(MONTH($A7)/3,0) -> Q3 | G7: =DAY($A7) -> 6 | H7: =WEEKDAY($A7,2) -> 4 | I7: =TEXT($A7,"dddd") -> Thursday | J7: =IF($H7>5,"Yes","No") -> No | K7: =IF(COUNTIF(Bank_Holidays!A:A,A7)>0,"Yes","No") -> No | L7: =IF(AND(J7="No",K7="No"),"Yes","No") -> Yes | M7: =_xlfn.ISOWEEKNUM(A7) -> 32 | N7: =IF(A7=EOMONTH(A7,0),"Yes","No") -> No | O7: =IF(A7=WORKDAY(EOMONTH(A7,0)+1,-1,Bank_Holidays!$A$2:$A$25),"Yes","No") -> No | P7: =IF( AND( TEXT(A7,"dddd")="Friday", MONTH(A7+7)<>MONTH(A7) ), "Yes", "No" ) -> No | Q7: =IF( AND( TEXT(A7,"dddd")="Thursday", MONTH(A7+7)<>MONTH(A7) ), "Yes", "No" ) -> No | R7: =IF(L7="yes",1)+IF(L7="no",0,IF(AND(L12="no",L11="no",L10="no",L9="no",L8="no"),5,IF(AND(L11="no",L10="no",L9="no",L8="no"),4,IF(AND(L10="no",L9="no",L8="no"),3,IF(AND(L9="no",L8="no"),2,IF(L8="no",1)))))) -> 1 | S7: =MOD(A7-Fortnightly_Model!$M$1,14) -> 12 | T7: =MOD(A7-FourWeekly_Model!$M$1,28) -> 12
A8: =A7+1 -> 46241 | B8: =YEAR(A8) -> 2026 | C8: =MONTH(A8) -> 8 | D8: =TEXT(A8,"mmmm") -> August | E8: =TEXT(A8,"mmm-yy") -> Aug-26 | F8: ="Q"&ROUNDUP(MONTH($A8)/3,0) -> Q3 | G8: =DAY($A8) -> 7 | H8: =WEEKDAY($A8,2) -> 5 | I8: =TEXT($A8,"dddd") -> Friday | J8: =IF($H8>5,"Yes","No") -> No | K8: =IF(COUNTIF(Bank_Holidays!A:A,A8)>0,"Yes","No") -> No | L8: =IF(AND(J8="No",K8="No"),"Yes","No") -> Yes | M8: =_xlfn.ISOWEEKNUM(A8) -> 32 | N8: =IF(A8=EOMONTH(A8,0),"Yes","No") -> No | O8: =IF(A8=WORKDAY(EOMONTH(A8,0)+1,-1,Bank_Holidays!$A$2:$A$25),"Yes","No") -> No | P8: =IF( AND( TEXT(A8,"dddd")="Friday", MONTH(A8+7)<>MONTH(A8) ), "Yes", "No" ) -> No | Q8: =IF( AND( TEXT(A8,"dddd")="Thursday", MONTH(A8+7)<>MONTH(A8) ), "Yes", "No" ) -> No | R8: =IF(L8="yes",1)+IF(L8="no",0,IF(AND(L13="no",L12="no",L11="no",L10="no",L9="no"),5,IF(AND(L12="no",L11="no",L10="no",L9="no"),4,IF(AND(L11="no",L10="no",L9="no"),3,IF(AND(L10="no",L9="no"),2,IF(L9="no",1)))))) -> 3 | S8: =MOD(A8-Fortnightly_Model!$M$1,14) -> 13 | T8: =MOD(A8-FourWeekly_Model!$M$1,28) -> 13
A9: =A8+1 -> 46242 | B9: =YEAR(A9) -> 2026 | C9: =MONTH(A9) -> 8 | D9: =TEXT(A9,"mmmm") -> August | E9: =TEXT(A9,"mmm-yy") -> Aug-26 | F9: ="Q"&ROUNDUP(MONTH($A9)/3,0) -> Q3 | G9: =DAY($A9) -> 8 | H9: =WEEKDAY($A9,2) -> 6 | I9: =TEXT($A9,"dddd") -> Saturday | J9: =IF($H9>5,"Yes","No") -> Yes | K9: =IF(COUNTIF(Bank_Holidays!A:A,A9)>0,"Yes","No") -> No | L9: =IF(AND(J9="No",K9="No"),"Yes","No") -> No | M9: =_xlfn.ISOWEEKNUM(A9) -> 32 | N9: =IF(A9=EOMONTH(A9,0),"Yes","No") -> No | O9: =IF(A9=WORKDAY(EOMONTH(A9,0)+1,-1,Bank_Holidays!$A$2:$A$25),"Yes","No") -> No | P9: =IF( AND( TEXT(A9,"dddd")="Friday", MONTH(A9+7)<>MONTH(A9) ), "Yes", "No" ) -> No | Q9: =IF( AND( TEXT(A9,"dddd")="Thursday", MONTH(A9+7)<>MONTH(A9) ), "Yes", "No" ) -> No | R9: =IF(L9="yes",1)+IF(L9="no",0,IF(AND(L14="no",L13="no",L12="no",L11="no",L10="no"),5,IF(AND(L13="no",L12="no",L11="no",L10="no"),4,IF(AND(L12="no",L11="no",L10="no"),3,IF(AND(L11="no",L10="no"),2,IF(L10="no",1)))))) -> 0 | S9: =MOD(A9-Fortnightly_Model!$M$1,14) -> 0 | T9: =MOD(A9-FourWeekly_Model!$M$1,28) -> 14
A10: =A9+1 -> 46243 | B10: =YEAR(A10) -> 2026 | C10: =MONTH(A10) -> 8 | D10: =TEXT(A10,"mmmm") -> August | E10: =TEXT(A10,"mmm-yy") -> Aug-26 | F10: ="Q"&ROUNDUP(MONTH($A10)/3,0) -> Q3 | G10: =DAY($A10) -> 9 | H10: =WEEKDAY($A10,2) -> 7 | I10: =TEXT($A10,"dddd") -> Sunday | J10: =IF($H10>5,"Yes","No") -> Yes | K10: =IF(COUNTIF(Bank_Holidays!A:A,A10)>0,"Yes","No") -> No | L10: =IF(AND(J10="No",K10="No"),"Yes","No") -> No | M10: =_xlfn.ISOWEEKNUM(A10) -> 32 | N10: =IF(A10=EOMONTH(A10,0),"Yes","No") -> No | O10: =IF(A10=WORKDAY(EOMONTH(A10,0)+1,-1,Bank_Holidays!$A$2:$A$25),"Yes","No") -> No | P10: =IF( AND( TEXT(A10,"dddd")="Friday", MONTH(A10+7)<>MONTH(A10) ), "Yes", "No" ) -> No | Q10: =IF( AND( TEXT(A10,"dddd")="Thursday", MONTH(A10+7)<>MONTH(A10) ), "Yes", "No" ) -> No | R10: =IF(L10="yes",1)+IF(L10="no",0,IF(AND(L15="no",L14="no",L13="no",L12="no",L11="no"),5,IF(AND(L14="no",L13="no",L12="no",L11="no"),4,IF(AND(L13="no",L12="no",L11="no"),3,IF(AND(L12="no",L11="no"),2,IF(L11="no",1)))))) -> 0 | S10: =MOD(A10-Fortnightly_Model!$M$1,14) -> 1 | T10: =MOD(A10-FourWeekly_Model!$M$1,28) -> 15
A11: =A10+1 -> 46244 | B11: =YEAR(A11) -> 2026 | C11: =MONTH(A11) -> 8 | D11: =TEXT(A11,"mmmm") -> August | E11: =TEXT(A11,"mmm-yy") -> Aug-26 | F11: ="Q"&ROUNDUP(MONTH($A11)/3,0) -> Q3 | G11: =DAY($A11) -> 10 | H11: =WEEKDAY($A11,2) -> 1 | I11: =TEXT($A11,"dddd") -> Monday | J11: =IF($H11>5,"Yes","No") -> No | K11: =IF(COUNTIF(Bank_Holidays!A:A,A11)>0,"Yes","No") -> No | L11: =IF(AND(J11="No",K11="No"),"Yes","No") -> Yes | M11: =_xlfn.ISOWEEKNUM(A11) -> 33 | N11: =IF(A11=EOMONTH(A11,0),"Yes","No") -> No | O11: =IF(A11=WORKDAY(EOMONTH(A11,0)+1,-1,Bank_Holidays!$A$2:$A$25),"Yes","No") -> No | P11: =IF( AND( TEXT(A11,"dddd")="Friday", MONTH(A11+7)<>MONTH(A11) ), "Yes", "No" ) -> No | Q11: =IF( AND( TEXT(A11,"dddd")="Thursday", MONTH(A11+7)<>MONTH(A11) ), "Yes", "No" ) -> No | R11: =IF(L11="yes",1)+IF(L11="no",0,IF(AND(L16="no",L15="no",L14="no",L13="no",L12="no"),5,IF(AND(L15="no",L14="no",L13="no",L12="no"),4,IF(AND(L14="no",L13="no",L12="no"),3,IF(AND(L13="no",L12="no"),2,IF(L12="no",1)))))) -> 1 | S11: =MOD(A11-Fortnightly_Model!$M$1,14) -> 2 | T11: =MOD(A11-FourWeekly_Model!$M$1,28) -> 16
A12: =A11+1 -> 46245 | B12: =YEAR(A12) -> 2026 | C12: =MONTH(A12) -> 8 | D12: =TEXT(A12,"mmmm") -> August | E12: =TEXT(A12,"mmm-yy") -> Aug-26 | F12: ="Q"&ROUNDUP(MONTH($A12)/3,0) -> Q3 | G12: =DAY($A12) -> 11 | H12: =WEEKDAY($A12,2) -> 2 | I12: =TEXT($A12,"dddd") -> Tuesday | J12: =IF($H12>5,"Yes","No") -> No | K12: =IF(COUNTIF(Bank_Holidays!A:A,A12)>0,"Yes","No") -> No | L12: =IF(AND(J12="No",K12="No"),"Yes","No") -> Yes | M12: =_xlfn.ISOWEEKNUM(A12) -> 33 | N12: =IF(A12=EOMONTH(A12,0),"Yes","No") -> No | O12: =IF(A12=WORKDAY(EOMONTH(A12,0)+1,-1,Bank_Holidays!$A$2:$A$25),"Yes","No") -> No | P12: =IF( AND( TEXT(A12,"dddd")="Friday", MONTH(A12+7)<>MONTH(A12) ), "Yes", "No" ) -> No | Q12: =IF( AND( TEXT(A12,"dddd")="Thursday", MONTH(A12+7)<>MONTH(A12) ), "Yes", "No" ) -> No | R12: =IF(L12="yes",1)+IF(L12="no",0,IF(AND(L17="no",L16="no",L15="no",L14="no",L13="no"),5,IF(AND(L16="no",L15="no",L14="no",L13="no"),4,IF(AND(L15="no",L14="no",L13="no"),3,IF(AND(L14="no",L13="no"),2,IF(L13="no",1)))))) -> 1 | S12: =MOD(A12-Fortnightly_Model!$M$1,14) -> 3 | T12: =MOD(A12-FourWeekly_Model!$M$1,28) -> 17
A13: =A12+1 -> 46246 | B13: =YEAR(A13) -> 2026 | C13: =MONTH(A13) -> 8 | D13: =TEXT(A13,"mmmm") -> August | E13: =TEXT(A13,"mmm-yy") -> Aug-26 | F13: ="Q"&ROUNDUP(MONTH($A13)/3,0) -> Q3 | G13: =DAY($A13) -> 12 | H13: =WEEKDAY($A13,2) -> 3 | I13: =TEXT($A13,"dddd") -> Wednesday | J13: =IF($H13>5,"Yes","No") -> No | K13: =IF(COUNTIF(Bank_Holidays!A:A,A13)>0,"Yes","No") -> No | L13: =IF(AND(J13="No",K13="No"),"Yes","No") -> Yes | M13: =_xlfn.ISOWEEKNUM(A13) -> 33 | N13: =IF(A13=EOMONTH(A13,0),"Yes","No") -> No | O13: =IF(A13=WORKDAY(EOMONTH(A13,0)+1,-1,Bank_Holidays!$A$2:$A$25),"Yes","No") -> No | P13: =IF( AND( TEXT(A13,"dddd")="Friday", MONTH(A13+7)<>MONTH(A13) ), "Yes", "No" ) -> No | Q13: =IF( AND( TEXT(A13,"dddd")="Thursday", MONTH(A13+7)<>MONTH(A13) ), "Yes", "No" ) -> No | R13: =IF(L13="yes",1)+IF(L13="no",0,IF(AND(L18="no",L17="no",L16="no",L15="no",L14="no"),5,IF(AND(L17="no",L16="no",L15="no",L14="no"),4,IF(AND(L16="no",L15="no",L14="no"),3,IF(AND(L15="no",L14="no"),2,IF(L14="no",1)))))) -> 1 | S13: =MOD(A13-Fortnightly_Model!$M$1,14) -> 4 | T13: =MOD(A13-FourWeekly_Model!$M$1,28) -> 18
A14: =A13+1 -> 46247 | B14: =YEAR(A14) -> 2026 | C14: =MONTH(A14) -> 8 | D14: =TEXT(A14,"mmmm") -> August | E14: =TEXT(A14,"mmm-yy") -> Aug-26 | F14: ="Q"&ROUNDUP(MONTH($A14)/3,0) -> Q3 | G14: =DAY($A14) -> 13 | H14: =WEEKDAY($A14,2) -> 4 | I14: =TEXT($A14,"dddd") -> Thursday | J14: =IF($H14>5,"Yes","No") -> No | K14: =IF(COUNTIF(Bank_Holidays!A:A,A14)>0,"Yes","No") -> No | L14: =IF(AND(J14="No",K14="No"),"Yes","No") -> Yes | M14: =_xlfn.ISOWEEKNUM(A14) -> 33 | N14: =IF(A14=EOMONTH(A14,0),"Yes","No") -> No | O14: =IF(A14=WORKDAY(EOMONTH(A14,0)+1,-1,Bank_Holidays!$A$2:$A$25),"Yes","No") -> No | P14: =IF( AND( TEXT(A14,"dddd")="Friday", MONTH(A14+7)<>MONTH(A14) ), "Yes", "No" ) -> No | Q14: =IF( AND( TEXT(A14,"dddd")="Thursday", MONTH(A14+7)<>MONTH(A14) ), "Yes", "No" ) -> No | R14: =IF(L14="yes",1)+IF(L14="no",0,IF(AND(L19="no",L18="no",L17="no",L16="no",L15="no"),5,IF(AND(L18="no",L17="no",L16="no",L15="no"),4,IF(AND(L17="no",L16="no",L15="no"),3,IF(AND(L16="no",L15="no"),2,IF(L15="no",1)))))) -> 1 | S14: =MOD(A14-Fortnightly_Model!$M$1,14) -> 5 | T14: =MOD(A14-FourWeekly_Model!$M$1,28) -> 19
... A532: =A531+1 -> 46765 | B532: =YEAR(A532) -> 2028 | C532: =MONTH(A532) -> 1 | D532: =TEXT(A532,"mmmm") -> January | E532: =TEXT(A532,"mmm-yy") -> Jan-28 | F532: ="Q"&ROUNDUP(MONTH($A532)/3,0) -> Q1 | G532: =DAY($A532) -> 13 | H532: =WEEKDAY($A532,2) -> 4 | I532: =TEXT($A532,"dddd") -> Thursday | J532: =IF($H532>5,"Yes","No") -> No | K532: =IF(COUNTIF(Bank_Holidays!A:A,A532)>0,"Yes","No") -> No | L532: =IF(AND(J532="No",K532="No"),"Yes","No") -> Yes | M532: =_xlfn.ISOWEEKNUM(A532) -> 2 | N532: =IF(A532=EOMONTH(A532,0),"Yes","No") -> No | O532: =IF(A532=WORKDAY(EOMONTH(A532,0)+1,-1,Bank_Holidays!$A$2:$A$25),"Yes","No") -> No | P532: =IF( AND( TEXT(A532,"dddd")="Friday", MONTH(A532+7)<>MONTH(A532) ), "Yes", "No" ) -> No | Q532: =IF( AND( TEXT(A532,"dddd")="Thursday", MONTH(A532+7)<>MONTH(A532) ), "Yes", "No" ) -> No | R532: =IF(L532="yes",1)+IF(L532="no",0,IF(AND(L537="no",L536="no",L535="no",L534="no",L533="no"),5,IF(AND(L536="no",L535="no",L534="no",L533="no"),4,IF(AND(L535="no",L534="no",L533="no"),3,IF(AND(L534="no",L533="no"),2,IF(L533="no",1)))))) -> 1 | S532: =MOD(A532-Fortnightly_Model!$M$1,14) -> 5 | T532: =MOD(A532-FourWeekly_Model!$M$1,28) -> 5
A533: =A532+1 -> 46766 | B533: =YEAR(A533) -> 2028 | C533: =MONTH(A533) -> 1 | D533: =TEXT(A533,"mmmm") -> January | E533: =TEXT(A533,"mmm-yy") -> Jan-28 | F533: ="Q"&ROUNDUP(MONTH($A533)/3,0) -> Q1 | G533: =DAY($A533) -> 14 | H533: =WEEKDAY($A533,2) -> 5 | I533: =TEXT($A533,"dddd") -> Friday | J533: =IF($H533>5,"Yes","No") -> No | K533: =IF(COUNTIF(Bank_Holidays!A:A,A533)>0,"Yes","No") -> No | L533: =IF(AND(J533="No",K533="No"),"Yes","No") -> Yes | M533: =_xlfn.ISOWEEKNUM(A533) -> 2 | N533: =IF(A533=EOMONTH(A533,0),"Yes","No") -> No | O533: =IF(A533=WORKDAY(EOMONTH(A533,0)+1,-1,Bank_Holidays!$A$2:$A$25),"Yes","No") -> No | P533: =IF( AND( TEXT(A533,"dddd")="Friday", MONTH(A533+7)<>MONTH(A533) ), "Yes", "No" ) -> No | Q533: =IF( AND( TEXT(A533,"dddd")="Thursday", MONTH(A533+7)<>MONTH(A533) ), "Yes", "No" ) -> No | R533: =IF(L533="yes",1)+IF(L533="no",0,IF(AND(L538="no",L537="no",L536="no",L535="no",L534="no"),5,IF(AND(L537="no",L536="no",L535="no",L534="no"),4,IF(AND(L536="no",L535="no",L534="no"),3,IF(AND(L535="no",L534="no"),2,IF(L534="no",1)))))) -> 3
A534: =A533+1 -> 46767 | B534: =YEAR(A534) -> 2028 | C534: =MONTH(A534) -> 1 | D534: =TEXT(A534,"mmmm") -> January | E534: =TEXT(A534,"mmm-yy") -> Jan-28 | F534: ="Q"&ROUNDUP(MONTH($A534)/3,0) -> Q1 | G534: =DAY($A534) -> 15 | H534: =WEEKDAY($A534,2) -> 6 | I534: =TEXT($A534,"dddd") -> Saturday | J534: =IF($H534>5,"Yes","No") -> Yes | K534: =IF(COUNTIF(Bank_Holidays!A:A,A534)>0,"Yes","No") -> No | L534: =IF(AND(J534="No",K534="No"),"Yes","No") -> No | M534: =_xlfn.ISOWEEKNUM(A534) -> 2 | N534: =IF(A534=EOMONTH(A534,0),"Yes","No") -> No | O534: =IF(A534=WORKDAY(EOMONTH(A534,0)+1,-1,Bank_Holidays!$A$2:$A$25),"Yes","No") -> No | P534: =IF( AND( TEXT(A534,"dddd")="Friday", MONTH(A534+7)<>MONTH(A534) ), "Yes", "No" ) -> No | Q534: =IF( AND( TEXT(A534,"dddd")="Thursday", MONTH(A534+7)<>MONTH(A534) ), "Yes", "No" ) -> No | R534: =IF(L534="yes",1)+IF(L534="no",0,IF(AND(L539="no",L538="no",L537="no",L536="no",L535="no"),5,IF(AND(L538="no",L537="no",L536="no",L535="no"),4,IF(AND(L537="no",L536="no",L535="no"),3,IF(AND(L536="no",L535="no"),2,IF(L535="no",1)))))) -> 0
A535: =A534+1 -> 46768 | B535: =YEAR(A535) -> 2028 | C535: =MONTH(A535) -> 1 | D535: =TEXT(A535,"mmmm") -> January | E535: =TEXT(A535,"mmm-yy") -> Jan-28 | F535: ="Q"&ROUNDUP(MONTH($A535)/3,0) -> Q1 | G535: =DAY($A535) -> 16 | H535: =WEEKDAY($A535,2) -> 7 | I535: =TEXT($A535,"dddd") -> Sunday | J535: =IF($H535>5,"Yes","No") -> Yes | K535: =IF(COUNTIF(Bank_Holidays!A:A,A535)>0,"Yes","No") -> No | L535: =IF(AND(J535="No",K535="No"),"Yes","No") -> No | M535: =_xlfn.ISOWEEKNUM(A535) -> 2 | N535: =IF(A535=EOMONTH(A535,0),"Yes","No") -> No | O535: =IF(A535=WORKDAY(EOMONTH(A535,0)+1,-1,Bank_Holidays!$A$2:$A$25),"Yes","No") -> No | P535: =IF( AND( TEXT(A535,"dddd")="Friday", MONTH(A535+7)<>MONTH(A535) ), "Yes", "No" ) -> No | Q535: =IF( AND( TEXT(A535,"dddd")="Thursday", MONTH(A535+7)<>MONTH(A535) ), "Yes", "No" ) -> No | R535: =IF(L535="yes",1)+IF(L535="no",0,IF(AND(L540="no",L539="no",L538="no",L537="no",L536="no"),5,IF(AND(L539="no",L538="no",L537="no",L536="no"),4,IF(AND(L538="no",L537="no",L536="no"),3,IF(AND(L537="no",L536="no"),2,IF(L536="no",1)))))) -> 0
A536: =A535+1 -> 46769 | B536: =YEAR(A536) -> 2028 | C536: =MONTH(A536) -> 1 | D536: =TEXT(A536,"mmmm") -> January | E536: =TEXT(A536,"mmm-yy") -> Jan-28 | F536: ="Q"&ROUNDUP(MONTH($A536)/3,0) -> Q1 | G536: =DAY($A536) -> 17 | H536: =WEEKDAY($A536,2) -> 1 | I536: =TEXT($A536,"dddd") -> Monday | J536: =IF($H536>5,"Yes","No") -> No | K536: =IF(COUNTIF(Bank_Holidays!A:A,A536)>0,"Yes","No") -> No | L536: =IF(AND(J536="No",K536="No"),"Yes","No") -> Yes | M536: =_xlfn.ISOWEEKNUM(A536) -> 3 | N536: =IF(A536=EOMONTH(A536,0),"Yes","No") -> No | O536: =IF(A536=WORKDAY(EOMONTH(A536,0)+1,-1,Bank_Holidays!$A$2:$A$25),"Yes","No") -> No | P536: =IF( AND( TEXT(A536,"dddd")="Friday", MONTH(A536+7)<>MONTH(A536) ), "Yes", "No" ) -> No | Q536: =IF( AND( TEXT(A536,"dddd")="Thursday", MONTH(A536+7)<>MONTH(A536) ), "Yes", "No" ) -> No | R536: =IF(L536="yes",1)+IF(L536="no",0,IF(AND(L541="no",L540="no",L539="no",L538="no",L537="no"),5,IF(AND(L540="no",L539="no",L538="no",L537="no"),4,IF(AND(L539="no",L538="no",L537="no"),3,IF(AND(L538="no",L537="no"),2,IF(L537="no",1)))))) -> 1
A537: =A536+1 -> 46770 | B537: =YEAR(A537) -> 2028 | C537: =MONTH(A537) -> 1 | D537: =TEXT(A537,"mmmm") -> January | E537: =TEXT(A537,"mmm-yy") -> Jan-28 | F537: ="Q"&ROUNDUP(MONTH($A537)/3,0) -> Q1 | G537: =DAY($A537) -> 18 | H537: =WEEKDAY($A537,2) -> 2 | I537: =TEXT($A537,"dddd") -> Tuesday | J537: =IF($H537>5,"Yes","No") -> No | K537: =IF(COUNTIF(Bank_Holidays!A:A,A537)>0,"Yes","No") -> No | L537: =IF(AND(J537="No",K537="No"),"Yes","No") -> Yes | M537: =_xlfn.ISOWEEKNUM(A537) -> 3 | N537: =IF(A537=EOMONTH(A537,0),"Yes","No") -> No | O537: =IF(A537=WORKDAY(EOMONTH(A537,0)+1,-1,Bank_Holidays!$A$2:$A$25),"Yes","No") -> No | P537: =IF( AND( TEXT(A537,"dddd")="Friday", MONTH(A537+7)<>MONTH(A537) ), "Yes", "No" ) -> No | Q537: =IF( AND( TEXT(A537,"dddd")="Thursday", MONTH(A537+7)<>MONTH(A537) ), "Yes", "No" ) -> No | R537: =IF(L537="yes",1)+IF(L537="no",0,IF(AND(L542="no",L541="no",L540="no",L539="no",L538="no"),5,IF(AND(L541="no",L540="no",L539="no",L538="no"),4,IF(AND(L540="no",L539="no",L538="no"),3,IF(AND(L539="no",L538="no"),2,IF(L538="no",1)))))) -> 1
A538: =A537+1 -> 46771 | B538: =YEAR(A538) -> 2028 | C538: =MONTH(A538) -> 1 | D538: =TEXT(A538,"mmmm") -> January | E538: =TEXT(A538,"mmm-yy") -> Jan-28 | F538: ="Q"&ROUNDUP(MONTH($A538)/3,0) -> Q1 | G538: =DAY($A538) -> 19 | H538: =WEEKDAY($A538,2) -> 3 | I538: =TEXT($A538,"dddd") -> Wednesday | J538: =IF($H538>5,"Yes","No") -> No | K538: =IF(COUNTIF(Bank_Holidays!A:A,A538)>0,"Yes","No") -> No | L538: =IF(AND(J538="No",K538="No"),"Yes","No") -> Yes | M538: =_xlfn.ISOWEEKNUM(A538) -> 3 | N538: =IF(A538=EOMONTH(A538,0),"Yes","No") -> No | O538: =IF(A538=WORKDAY(EOMONTH(A538,0)+1,-1,Bank_Holidays!$A$2:$A$25),"Yes","No") -> No | P538: =IF( AND( TEXT(A538,"dddd")="Friday", MONTH(A538+7)<>MONTH(A538) ), "Yes", "No" ) -> No | Q538: =IF( AND( TEXT(A538,"dddd")="Thursday", MONTH(A538+7)<>MONTH(A538) ), "Yes", "No" ) -> No | R538: =IF(L538="yes",1)+IF(L538="no",0,IF(AND(L543="no",L542="no",L541="no",L540="no",L539="no"),5,IF(AND(L542="no",L541="no",L540="no",L539="no"),4,IF(AND(L541="no",L540="no",L539="no"),3,IF(AND(L540="no",L539="no"),2,IF(L539="no",1)))))) -> 1
A539: =A538+1 -> 46772 | B539: =YEAR(A539) -> 2028 | C539: =MONTH(A539) -> 1 | D539: =TEXT(A539,"mmmm") -> January | E539: =TEXT(A539,"mmm-yy") -> Jan-28 | F539: ="Q"&ROUNDUP(MONTH($A539)/3,0) -> Q1 | G539: =DAY($A539) -> 20 | H539: =WEEKDAY($A539,2) -> 4 | I539: =TEXT($A539,"dddd") -> Thursday | J539: =IF($H539>5,"Yes","No") -> No | K539: =IF(COUNTIF(Bank_Holidays!A:A,A539)>0,"Yes","No") -> No | L539: =IF(AND(J539="No",K539="No"),"Yes","No") -> Yes | M539: =_xlfn.ISOWEEKNUM(A539) -> 3 | N539: =IF(A539=EOMONTH(A539,0),"Yes","No") -> No | O539: =IF(A539=WORKDAY(EOMONTH(A539,0)+1,-1,Bank_Holidays!$A$2:$A$25),"Yes","No") -> No | P539: =IF( AND( TEXT(A539,"dddd")="Friday", MONTH(A539+7)<>MONTH(A539) ), "Yes", "No" ) -> No | Q539: =IF( AND( TEXT(A539,"dddd")="Thursday", MONTH(A539+7)<>MONTH(A539) ), "Yes", "No" ) -> No | R539: =IF(L539="yes",1)+IF(L539="no",0,IF(AND(L544="no",L543="no",L542="no",L541="no",L540="no"),5,IF(AND(L543="no",L542="no",L541="no",L540="no"),4,IF(AND(L542="no",L541="no",L540="no"),3,IF(AND(L541="no",L540="no"),2,IF(L540="no",1)))))) -> 1
A540: =A539+1 -> 46773 | B540: =YEAR(A540) -> 2028 | C540: =MONTH(A540) -> 1 | D540: =TEXT(A540,"mmmm") -> January | E540: =TEXT(A540,"mmm-yy") -> Jan-28 | F540: ="Q"&ROUNDUP(MONTH($A540)/3,0) -> Q1 | G540: =DAY($A540) -> 21 | H540: =WEEKDAY($A540,2) -> 5 | I540: =TEXT($A540,"dddd") -> Friday | J540: =IF($H540>5,"Yes","No") -> No | K540: =IF(COUNTIF(Bank_Holidays!A:A,A540)>0,"Yes","No") -> No | L540: =IF(AND(J540="No",K540="No"),"Yes","No") -> Yes | M540: =_xlfn.ISOWEEKNUM(A540) -> 3 | N540: =IF(A540=EOMONTH(A540,0),"Yes","No") -> No | O540: =IF(A540=WORKDAY(EOMONTH(A540,0)+1,-1,Bank_Holidays!$A$2:$A$25),"Yes","No") -> No | P540: =IF( AND( TEXT(A540,"dddd")="Friday", MONTH(A540+7)<>MONTH(A540) ), "Yes", "No" ) -> No | Q540: =IF( AND( TEXT(A540,"dddd")="Thursday", MONTH(A540+7)<>MONTH(A540) ), "Yes", "No" ) -> No | R540: =IF(L540="yes",1)+IF(L540="no",0,IF(AND(L545="no",L544="no",L543="no",L542="no",L541="no"),5,IF(AND(L544="no",L543="no",L542="no",L541="no"),4,IF(AND(L543="no",L542="no",L541="no"),3,IF(AND(L542="no",L541="no"),2,IF(L541="no",1)))))) -> 3
A541: =A540+1 -> 46774 | B541: =YEAR(A541) -> 2028 | C541: =MONTH(A541) -> 1 | D541: =TEXT(A541,"mmmm") -> January | E541: =TEXT(A541,"mmm-yy") -> Jan-28 | F541: ="Q"&ROUNDUP(MONTH($A541)/3,0) -> Q1 | G541: =DAY($A541) -> 22 | H541: =WEEKDAY($A541,2) -> 6 | I541: =TEXT($A541,"dddd") -> Saturday | J541: =IF($H541>5,"Yes","No") -> Yes | K541: =IF(COUNTIF(Bank_Holidays!A:A,A541)>0,"Yes","No") -> No | L541: =IF(AND(J541="No",K541="No"),"Yes","No") -> No | M541: =_xlfn.ISOWEEKNUM(A541) -> 3 | N541: =IF(A541=EOMONTH(A541,0),"Yes","No") -> No | O541: =IF(A541=WORKDAY(EOMONTH(A541,0)+1,-1,Bank_Holidays!$A$2:$A$25),"Yes","No") -> No | P541: =IF( AND( TEXT(A541,"dddd")="Friday", MONTH(A541+7)<>MONTH(A541) ), "Yes", "No" ) -> No | Q541: =IF( AND( TEXT(A541,"dddd")="Thursday", MONTH(A541+7)<>MONTH(A541) ), "Yes", "No" ) -> No | R541: =IF(L541="yes",1)+IF(L541="no",0,IF(AND(L546="no",L545="no",L544="no",L543="no",L542="no"),5,IF(AND(L545="no",L544="no",L543="no",L542="no"),4,IF(AND(L544="no",L543="no",L542="no"),3,IF(AND(L543="no",L542="no"),2,IF(L542="no",1)))))) -> 0
A542: =A541+1 -> 46775 | B542: =YEAR(A542) -> 2028 | C542: =MONTH(A542) -> 1 | D542: =TEXT(A542,"mmmm") -> January | E542: =TEXT(A542,"mmm-yy") -> Jan-28 | F542: ="Q"&ROUNDUP(MONTH($A542)/3,0) -> Q1 | G542: =DAY($A542) -> 23 | H542: =WEEKDAY($A542,2) -> 7 | I542: =TEXT($A542,"dddd") -> Sunday | J542: =IF($H542>5,"Yes","No") -> Yes | K542: =IF(COUNTIF(Bank_Holidays!A:A,A542)>0,"Yes","No") -> No | L542: =IF(AND(J542="No",K542="No"),"Yes","No") -> No | M542: =_xlfn.ISOWEEKNUM(A542) -> 3 | N542: =IF(A542=EOMONTH(A542,0),"Yes","No") -> No | O542: =IF(A542=WORKDAY(EOMONTH(A542,0)+1,-1,Bank_Holidays!$A$2:$A$25),"Yes","No") -> No | P542: =IF( AND( TEXT(A542,"dddd")="Friday", MONTH(A542+7)<>MONTH(A542) ), "Yes", "No" ) -> No | Q542: =IF( AND( TEXT(A542,"dddd")="Thursday", MONTH(A542+7)<>MONTH(A542) ), "Yes", "No" ) -> No | R542: =IF(L542="yes",1)+IF(L542="no",0,IF(AND(L547="no",L546="no",L545="no",L544="no",L543="no"),5,IF(AND(L546="no",L545="no",L544="no",L543="no"),4,IF(AND(L545="no",L544="no",L543="no"),3,IF(AND(L544="no",L543="no"),2,IF(L543="no",1)))))) -> 0
A543: =A542+1 -> 46776 | B543: =YEAR(A543) -> 2028 | C543: =MONTH(A543) -> 1 | D543: =TEXT(A543,"mmmm") -> January | E543: =TEXT(A543,"mmm-yy") -> Jan-28 | F543: ="Q"&ROUNDUP(MONTH($A543)/3,0) -> Q1 | G543: =DAY($A543) -> 24 | H543: =WEEKDAY($A543,2) -> 1 | I543: =TEXT($A543,"dddd") -> Monday | J543: =IF($H543>5,"Yes","No") -> No | K543: =IF(COUNTIF(Bank_Holidays!A:A,A543)>0,"Yes","No") -> No | L543: =IF(AND(J543="No",K543="No"),"Yes","No") -> Yes | M543: =_xlfn.ISOWEEKNUM(A543) -> 4 | N543: =IF(A543=EOMONTH(A543,0),"Yes","No") -> No | O543: =IF(A543=WORKDAY(EOMONTH(A543,0)+1,-1,Bank_Holidays!$A$2:$A$25),"Yes","No") -> No | P543: =IF( AND( TEXT(A543,"dddd")="Friday", MONTH(A543+7)<>MONTH(A543) ), "Yes", "No" ) -> No | Q543: =IF( AND( TEXT(A543,"dddd")="Thursday", MONTH(A543+7)<>MONTH(A543) ), "Yes", "No" ) -> No | R543: =IF(L543="yes",1)+IF(L543="no",0,IF(AND(L548="no",L547="no",L546="no",L545="no",L544="no"),5,IF(AND(L547="no",L546="no",L545="no",L544="no"),4,IF(AND(L546="no",L545="no",L544="no"),3,IF(AND(L545="no",L544="no"),2,IF(L544="no",1)))))) -> 1
A544: =A543+1 -> 46777 | B544: =YEAR(A544) -> 2028 | C544: =MONTH(A544) -> 1 | D544: =TEXT(A544,"mmmm") -> January | E544: =TEXT(A544,"mmm-yy") -> Jan-28 | F544: ="Q"&ROUNDUP(MONTH($A544)/3,0) -> Q1 | G544: =DAY($A544) -> 25 | H544: =WEEKDAY($A544,2) -> 2 | I544: =TEXT($A544,"dddd") -> Tuesday | J544: =IF($H544>5,"Yes","No") -> No | K544: =IF(COUNTIF(Bank_Holidays!A:A,A544)>0,"Yes","No") -> No | L544: =IF(AND(J544="No",K544="No"),"Yes","No") -> Yes | M544: =_xlfn.ISOWEEKNUM(A544) -> 4 | N544: =IF(A544=EOMONTH(A544,0),"Yes","No") -> No | O544: =IF(A544=WORKDAY(EOMONTH(A544,0)+1,-1,Bank_Holidays!$A$2:$A$25),"Yes","No") -> No | P544: =IF( AND( TEXT(A544,"dddd")="Friday", MONTH(A544+7)<>MONTH(A544) ), "Yes", "No" ) -> No | Q544: =IF( AND( TEXT(A544,"dddd")="Thursday", MONTH(A544+7)<>MONTH(A544) ), "Yes", "No" ) -> No | R544: =IF(L544="yes",1)+IF(L544="no",0,IF(AND(L549="no",L548="no",L547="no",L546="no",L545="no"),5,IF(AND(L548="no",L547="no",L546="no",L545="no"),4,IF(AND(L547="no",L546="no",L545="no"),3,IF(AND(L546="no",L545="no"),2,IF(L545="no",1)))))) -> 1
... A1377: =A1376+1 -> 47610 | B1377: =YEAR(A1377) -> 2030 | C1377: =MONTH(A1377) -> 5 | D1377: =TEXT(A1377,"mmmm") -> May | E1377: =TEXT(A1377,"mmm-yy") -> May-30 | F1377: ="Q"&ROUNDUP(MONTH($A1377)/3,0) -> Q2 | G1377: =DAY($A1377) -> 7 | H1377: =WEEKDAY($A1377,2) -> 2 | I1377: =TEXT($A1377,"dddd") -> Tuesday | J1377: =IF($H1377>5,"Yes","No") -> No | K1377: =IF(COUNTIF(Bank_Holidays!A:A,A1377)>0,"Yes","No") -> No | L1377: =IF(AND(J1377="No",K1377="No"),"Yes","No") -> Yes | M1377: =_xlfn.ISOWEEKNUM(A1377) -> 19 | N1377: =IF(A1377=EOMONTH(A1377,0),"Yes","No") -> No | O1377: =IF(A1377=WORKDAY(EOMONTH(A1377,0)+1,-1,Bank_Holidays!$A$2:$A$25),"Yes","No") -> No | P1377: =IF( AND( TEXT(A1377,"dddd")="Friday", MONTH(A1377+7)<>MONTH(A1377) ), "Yes", "No" ) -> No | Q1377: =IF( AND( TEXT(A1377,"dddd")="Thursday", MONTH(A1377+7)<>MONTH(A1377) ), "Yes", "No" ) -> No | R1377: =IF(L1377="yes",1)+IF(L1377="no",0,IF(AND(L1382="no",L1381="no",L1380="no",L1379="no",L1378="no"),5,IF(AND(L1381="no",L1380="no",L1379="no",L1378="no"),4,IF(AND(L1380="no",L1379="no",L1378="no"),3,IF(AND(L1379="no",L1378="no"),2,IF(L1378="no",1)))))) -> 1

Sheet Daily_Calculations
A1: Date | B1: Working Day | C1: Last Working Day | D1: Last Friday | E1: Last Thursday | F1: Weekday | G1: Fortnight Offset | H1: FourWeek Offset | I1: Monthly Date | J1: Monthly % | K1: Weekly % | L1: Fortnightly % | M1: FourWeekly % | N1: Employee Total % | O1: Estimated Employees Paid | P1: Pensioners % | Q1: Estimated Pensions Paid | R1: Total | S1: Total
A2: =Calendar!A2 -> 46235 | B2: =Calendar!L2 -> No | C2: =Calendar!O2 -> No | D2: =Calendar!P2 -> No | E2: =Calendar!Q2 -> No | F2: =Calendar!I2 -> Saturday | G2: =Calendar!S2 -> 7 | H2: =Calendar!T2 -> 7 | I2: =IF(VLOOKUP(A2,Calendar!$A$1:$R$1377,18,0)=0,0,IF(VLOOKUP(A2,Calendar!$A$1:$R$1377,18,0)=1,INDEX(Monthly_Pay_Model!$A$9:$D$40,MATCH(TEXT(A2,"dd"),Monthly_Pay_Model!$C$9:$C$39,0),4),IF(VLOOKUP(A2,Calendar!$A$1:$R$1377,18,0)=2,SUM(INDEX(Monthly_Pay_Model!$A$9:$D$40,MATCH(TEXT(A2,"dd"),Monthly_Pay_Model!$C$9:$C$39,0),4),INDEX(Monthly_Pay_Model!$A$9:$D$40,MATCH(TEXT(A3,"dd"),Monthly_Pay_Model!$C$9:$C$39,0),4)),IF(VLOOKUP(A2,Calendar!$A$1:$R$1377,18,0)=3,SUM(INDEX(Monthly_Pay_Model!$A$9:$D$40,MATCH(TEXT(A2,"dd"),Monthly_Pay_Model!$C$9:$C$39,0),4),INDEX(Monthly_Pay_Model!$A$9:$D$40,MATCH(TEXT(A3,"dd"),Monthly_Pay_Model!$C$9:$C$39,0),4),INDEX(Monthly_Pay_Model!$A$9:$D$40,MATCH(TEXT(A4,"dd"),Monthly_Pay_Model!$C$9:$C$39,0),4)),IF(VLOOKUP(A2,Calendar!$A$1:$R$1377,18,0)=4,SUM(INDEX(Monthly_Pay_Model!$A$9:$D$40,MATCH(TEXT(A2,"dd"),Monthly_Pay_Model!$C$9:$C$39,0),4),INDEX(Monthly_Pay_Model!$A$9:$D$40,MATCH(TEXT(A3,"dd"),Monthly_Pay_Model!$C$9:$C$39,0),4),INDEX(Monthly_Pay_Model!$A$9:$D$40,MATCH(TEXT(A4,"dd"),Monthly_Pay_Model!$C$9:$C$39,0),4),INDEX(Monthly_Pay_Model!$A$9:$D$40,MATCH(TEXT(A5,"dd"),Monthly_Pay_Model!$C$9:$C$39,0),4)),IF(VLOOKUP(A2,Calendar!$A$1:$R$1377,18,0)=5,SUM(INDEX(Monthly_Pay_Model!$A$9:$D$40,MATCH(TEXT(A2,"dd"),Monthly_Pay_Model!$C$9:$C$39,0),4),INDEX(Monthly_Pay_Model!$A$9:$D$40,MATCH(TEXT(A3,"dd"),Monthly_Pay_Model!$C$9:$C$39,0),4),INDEX(Monthly_Pay_Model!$A$9:$D$40,MATCH(TEXT(A4,"dd"),Monthly_Pay_Model!$C$9:$C$39,0),4),INDEX(Monthly_Pay_Model!$A$9:$D$40,MATCH(TEXT(A5,"dd"),Monthly_Pay_Model!$C$9:$C$39,0),4),INDEX(Monthly_Pay_Model!$A$9:$D$40,MATCH(TEXT(A6,"dd"),Monthly_Pay_Model!$C$9:$C$39,0),4)),)))))) -> 0 | J2: =IF(C2="Yes",Monthly_Pay_Model!$D$2,0) +IF(Calendar!N2="Yes",Monthly_Pay_Model!$D$3,0) +IF(D2="Yes",Monthly_Pay_Model!$D$4,0) +IF(E2="Yes",Monthly_Pay_Model!$D$5,0) -> 0 | K2: =IF(VLOOKUP($A2,Calendar!$A$1:$R$1377,18,0)=0,0,IF(VLOOKUP($A2,Calendar!$A$1:$R$1377,18,0)=1,IFERROR(INDEX(Weekly_Model!$D$2:$D$9,MATCH(F2,Weekly_Model!$A$2:$A$9,0)),0),IF(VLOOKUP($A2,Calendar!$A$1:$R$1377,18,0)=2,SUM(IFERROR(INDEX(Weekly_Model!$D$2:$D$9,MATCH(F2,Weekly_Model!$A$2:$A$9,0)),0),IFERROR(INDEX(Weekly_Model!$D$2:$D$9,MATCH(F3,Weekly_Model!$A$2:$A$9,0)),0)),IF(VLOOKUP($A2,Calendar!$A$1:$R$1377,18,0)=3,SUM(IFERROR(INDEX(Weekly_Model!$D$2:$D$9,MATCH(F2,Weekly_Model!$A$2:$A$9,0)),0),IFERROR(INDEX(Weekly_Model!$D$2:$D$9,MATCH(F3,Weekly_Model!$A$2:$A$9,0)),0),IFERROR(INDEX(Weekly_Model!$D$2:$D$9,MATCH(F4,Weekly_Model!$A$2:$A$9,0)),0)),IF(VLOOKUP($A2,Calendar!$A$1:$R$1377,18,0)=4,SUM(IFERROR(INDEX(Weekly_Model!$D$2:$D$9,MATCH(F2,Weekly_Model!$A$2:$A$9,0)),0),IFERROR(INDEX(Weekly_Model!$D$2:$D$9,MATCH(F3,Weekly_Model!$A$2:$A$9,0)),0),IFERROR(INDEX(Weekly_Model!$D$2:$D$9,MATCH(F4,Weekly_Model!$A$2:$A$9,0)),0),IFERROR(INDEX(Weekly_Model!$D$2:$D$9,MATCH(F5,Weekly_Model!$A$2:$A$9,0)),0)),IF(VLOOKUP($A2,Calendar!$A$1:$R$1377,18,0)=5,SUM(IFERROR(INDEX(Weekly_Model!$D$2:$D$9,MATCH(F2,Weekly_Model!$A$2:$A$9,0)),0),IFERROR(INDEX(Weekly_Model!$D$2:$D$9,MATCH(F3,Weekly_Model!$A$2:$A$9,0)),0),IFERROR(INDEX(Weekly_Model!$D$2:$D$9,MATCH(F4,Weekly_Model!$A$2:$A$9,0)),0),IFERROR(INDEX(Weekly_Model!$D$2:$D$9,MATCH(F5,Weekly_Model!$A$2:$A$9,0)),0),IFERROR(INDEX(Weekly_Model!$D$2:$D$9,MATCH(F6,Weekly_Model!$A$2:$A$9,0)),0)),0)))))) -> 0 | L2: =IF(VLOOKUP($A2,Calendar!$A$1:$R$1377,18,0)=0,0,IF(VLOOKUP($A2,Calendar!$A$1:$R$1377,18,0)=1,IFERROR(INDEX(Fortnightly_Model!$D$2:$D$15,MATCH(G2,Fortnightly_Model!$B$2:$B$15,0)),0),IF(VLOOKUP($A2,Calendar!$A$1:$R$1377,18,0)=2,SUM(IFERROR(INDEX(Fortnightly_Model!$D$2:$D$15,MATCH(G2,Fortnightly_Model!$B$2:$B$15,0)),0),IFERROR(INDEX(Fortnightly_Model!$D$2:$D$15,MATCH(G3,Fortnightly_Model!$B$2:$B$15,0)),0)),IF(VLOOKUP($A2,Calendar!$A$1:$R$1377,18,0)=3,SUM(IFERROR(INDEX(Fortnightly_Model!$D$2:$D$15,MATCH(G2,Fortnightly_Model!$B$2:$B$15,0)),0),IFERROR(INDEX(Fortnightly_Model!$D$2:$D$15,MATCH(G3,Fortnightly_Model!$B$2:$B$15,0)),0),IFERROR(INDEX(Fortnightly_Model!$D$2:$D$15,MATCH(G4,Fortnightly_Model!$B$2:$B$15,0)),0)),IF(VLOOKUP($A2,Calendar!$A$1:$R$1377,18,0)=4,SUM(IFERROR(INDEX(Fortnightly_Model!$D$2:$D$15,MATCH(G2,Fortnightly_Model!$B$2:$B$15,0)),0),IFERROR(INDEX(Fortnightly_Model!$D$2:$D$15,MATCH(G3,Fortnightly_Model!$B$2:$B$15,0)),0),IFERROR(INDEX(Fortnightly_Model!$D$2:$D$15,MATCH(G4,Fortnightly_Model!$B$2:$B$15,0)),0),IFERROR(INDEX(Fortnightly_Model!$D$2:$D$15,MATCH(G5,Fortnightly_Model!$B$2:$B$15,0)),0)),IF(VLOOKUP($A2,Calendar!$A$1:$R$1377,18,0)=5,SUM(IFERROR(INDEX(Fortnightly_Model!$D$2:$D$15,MATCH(G2,Fortnightly_Model!$B$2:$B$15,0)),0),IFERROR(INDEX(Fortnightly_Model!$D$2:$D$15,MATCH(G3,Fortnightly_Model!$B$2:$B$15,0)),0),IFERROR(INDEX(Fortnightly_Model!$D$2:$D$15,MATCH(G4,Fortnightly_Model!$B$2:$B$15,0)),0),IFERROR(INDEX(Fortnightly_Model!$D$2:$D$15,MATCH(G5,Fortnightly_Model!$B$2:$B$15,0)),0),IFERROR(INDEX(Fortnightly_Model!$D$2:$D$15,MATCH(G6,Fortnightly_Model!$B$2:$B$15,0)),0)),0)))))) -> 0 | M2: =IF(VLOOKUP($A2,Calendar!$A$1:$R$1377,18,0)=0,0,IF(VLOOKUP($A2,Calendar!$A$1:$R$1377,18,0)=1,IFERROR(INDEX(FourWeekly_Model!$D$2:$D$29,MATCH(H2,FourWeekly_Model!$B$2:$B$29,0)),0),IF(VLOOKUP($A2,Calendar!$A$1:$R$1377,18,0)=2,SUM(IFERROR(INDEX(FourWeekly_Model!$D$2:$D$29,MATCH(H2,FourWeekly_Model!$B$2:$B$29,0)),0),IFERROR(INDEX(FourWeekly_Model!$D$2:$D$29,MATCH(H3,FourWeekly_Model!$B$2:$B$29,0)),0)),IF(VLOOKUP($A2,Calendar!$A$1:$R$1377,18,0)=3,SUM(IFERROR(INDEX(FourWeekly_Model!$D$2:$D$29,MATCH(H2,FourWeekly_Model!$B$2:$B$29,0)),0),IFERROR(INDEX(FourWeekly_Model!$D$2:$D$29,MATCH(H3,FourWeekly_Model!$B$2:$B$29,0)),0),IFERROR(INDEX(FourWeekly_Model!$D$2:$D$29,MATCH(H4,FourWeekly_Model!$B$2:$B$29,0)),0)),IF(VLOOKUP($A2,Calendar!$A$1:$R$1377,18,0)=4,SUM(IFERROR(INDEX(FourWeekly_Model!$D$2:$D$29,MATCH(H2,FourWeekly_Model!$B$2:$B$29,0)),0),IFERROR(INDEX(FourWeekly_Model!$D$2:$D$29,MATCH(H3,FourWeekly_Model!$B$2:$B$29,0)),0),IFERROR(INDEX(FourWeekly_Model!$D$2:$D$29,MATCH(H4,FourWeekly_Model!$B$2:$B$29,0)),0),IFERROR(INDEX(FourWeekly_Model!$D$2:$D$29,MATCH(H5,FourWeekly_Model!$B$2:$B$29,0)),0)),IF(VLOOKUP($A2,Calendar!$A$1:$R$1377,18,0)=5,SUM(IFERROR(INDEX(FourWeekly_Model!$D$2:$D$29,MATCH(H2,FourWeekly_Model!$B$2:$B$29,0)),0),IFERROR(INDEX(FourWeekly_Model!$D$2:$D$29,MATCH(H3,FourWeekly_Model!$B$2:$B$29,0)),0),IFERROR(INDEX(FourWeekly_Model!$D$2:$D$29,MATCH(H4,FourWeekly_Model!$B$2:$B$29,0)),0),IFERROR(INDEX(FourWeekly_Model!$D$2:$D$29,MATCH(H5,FourWeekly_Model!$B$2:$B$29,0)),0),IFERROR(INDEX(FourWeekly_Model!$D$2:$D$29,MATCH(H6,FourWeekly_Model!$B$2:$B$29,0)),0)),0)))))) -> 0 | N2: =SUM(I2:M2) -> 0 | O2: =Population_Data!$B$8*N2 -> 0 | P2: =IF(VLOOKUP($A2,Calendar!$A$1:$R$1377,18,0)=0,0,IF(VLOOKUP($A2,Calendar!$A$1:$R$1377,18,0)=1,IFERROR(INDEX(Pension_Model!$D$2:$D$29,MATCH(H2,Pension_Model!$B$2:$B$29,0)),0),IF(VLOOKUP($A2,Calendar!$A$1:$R$1377,18,0)=2,SUM(IFERROR(INDEX(Pension_Model!$D$2:$D$29,MATCH(H2,Pension_Model!$B$2:$B$29,0)),0),IFERROR(INDEX(Pension_Model!$D$2:$D$29,MATCH(H3,Pension_Model!$B$2:$B$29,0)),0)),IF(VLOOKUP($A2,Calendar!$A$1:$R$1377,18,0)=3,SUM(IFERROR(INDEX(Pension_Model!$D$2:$D$29,MATCH(H2,Pension_Model!$B$2:$B$29,0)),0),IFERROR(INDEX(Pension_Model!$D$2:$D$29,MATCH(H3,Pension_Model!$B$2:$B$29,0)),0),IFERROR(INDEX(Pension_Model!$D$2:$D$29,MATCH(H4,Pension_Model!$B$2:$B$29,0)),0)),IF(VLOOKUP($A2,Calendar!$A$1:$R$1377,18,0)=4,SUM(IFERROR(INDEX(Pension_Model!$D$2:$D$29,MATCH(H2,Pension_Model!$B$2:$B$29,0)),0),IFERROR(INDEX(Pension_Model!$D$2:$D$29,MATCH(H3,Pension_Model!$B$2:$B$29,0)),0),IFERROR(INDEX(Pension_Model!$D$2:$D$29,MATCH(H4,Pension_Model!$B$2:$B$29,0)),0),IFERROR(INDEX(Pension_Model!$D$2:$D$29,MATCH(H5,Pension_Model!$B$2:$B$29,0)),0)),IF(VLOOKUP($A2,Calendar!$A$1:$R$1377,18,0)=5,SUM(IFERROR(INDEX(Pension_Model!$D$2:$D$29,MATCH(H2,Pension_Model!$B$2:$B$29,0)),0),IFERROR(INDEX(Pension_Model!$D$2:$D$29,MATCH(H3,Pension_Model!$B$2:$B$29,0)),0),IFERROR(INDEX(Pension_Model!$D$2:$D$29,MATCH(H4,Pension_Model!$B$2:$B$29,0)),0),IFERROR(INDEX(Pension_Model!$D$2:$D$29,MATCH(H5,Pension_Model!$B$2:$B$29,0)),0),IFERROR(INDEX(Pension_Model!$D$2:$D$29,MATCH(H6,Pension_Model!$B$2:$B$29,0)),0)),0)))))) -> 0 | Q2: =Population_Data!$B$15*P2 -> 0 | S2: =SUM(Q2,O2) -> 0 | U2: =S2/Population_Data!$B$19 -> 0
